Traceback (most recent call last):
  File "/home/ubuntu/miniconda3/envs/jupybook/lib/python3.9/site-packages/jupyter_cache/executors/utils.py", line 51, in single_nb_execution
    executenb(
  File "/home/ubuntu/miniconda3/envs/jupybook/lib/python3.9/site-packages/nbclient/client.py", line 1112, in execute
    return NotebookClient(nb=nb, resources=resources, km=km, **kwargs).execute()
  File "/home/ubuntu/miniconda3/envs/jupybook/lib/python3.9/site-packages/nbclient/util.py", line 74, in wrapped
    return just_run(coro(*args, **kwargs))
  File "/home/ubuntu/miniconda3/envs/jupybook/lib/python3.9/site-packages/nbclient/util.py", line 53, in just_run
    return loop.run_until_complete(coro)
  File "/home/ubuntu/miniconda3/envs/jupybook/lib/python3.9/asyncio/base_events.py", line 642, in run_until_complete
    return future.result()
  File "/home/ubuntu/miniconda3/envs/jupybook/lib/python3.9/site-packages/nbclient/client.py", line 553, in async_execute
    await self.async_execute_cell(
  File "/home/ubuntu/miniconda3/envs/jupybook/lib/python3.9/site-packages/nbclient/client.py", line 857, in async_execute_cell
    self._check_raise_for_error(cell, exec_reply)
  File "/home/ubuntu/miniconda3/envs/jupybook/lib/python3.9/site-packages/nbclient/client.py", line 760, in _check_raise_for_error
    raise CellExecutionError.from_cell_and_msg(cell, exec_reply_content)
nbclient.exceptions.CellExecutionError: An error occurred while executing the following cell:
------------------
tags: [remove-output, remove-input]
from matplotlib.pyplot import *
from numpy import *
from myst_nb import glue

T = 0.01
x = linspace(0, 2 * T, 1000)
y = sin(2 * pi * 1000  * x) + 1 / 2 * sin(2 * pi * 1000  * x) * sin(2 * pi * 100  * x)

f, ax = subplots(figsize=(9,6))
f.suptitle('Signal Modul√© en amplitude')

ax.set_xlabel('temps(ms)')
ax.set_ylabel('VE(V)')

ax.plot(x * 1000, y, label="m=1/2")

ax.legend()

glue('sig_mod', f)
------------------

[0;31m---------------------------------------------------------------------------[0m
[0;31mNameError[0m                                 Traceback (most recent call last)
[0;32m<ipython-input-1-d2e1f4415ab1>[0m in [0;36m<module>[0;34m[0m
[0;32m----> 1[0;31m [0mtags[0m[0;34m:[0m [0;34m[[0m[0mremove[0m[0;34m-[0m[0moutput[0m[0;34m,[0m [0mremove[0m[0;34m-[0m[0minput[0m[0;34m][0m[0;34m[0m[0;34m[0m[0m
[0m[1;32m      2[0m [0;32mfrom[0m [0mmatplotlib[0m[0;34m.[0m[0mpyplot[0m [0;32mimport[0m [0;34m*[0m[0;34m[0m[0;34m[0m[0m
[1;32m      3[0m [0;32mfrom[0m [0mnumpy[0m [0;32mimport[0m [0;34m*[0m[0;34m[0m[0;34m[0m[0m
[1;32m      4[0m [0;32mfrom[0m [0mmyst_nb[0m [0;32mimport[0m [0mglue[0m[0;34m[0m[0;34m[0m[0m
[1;32m      5[0m [0;34m[0m[0m

[0;31mNameError[0m: name 'remove' is not defined
NameError: name 'remove' is not defined

